Workbook

Sheet Voyage 1 Pengerang -> Uban -> T
A1: Voyage 1
I2: Ringkasan Expense OPEX | K2: IDR | L2: USD
A3: Route: | B3: Malaysia Loading -> Indonesia Discharging -> Singapore Bunkering | I3: Pre Voyage & Initial Loading
A4: Duration: | B4: July 25 – Aug 26 (32 Days) | I4: Legalitas & Survey | K4: =SUMIF($A$22:$A$63,I4,$G$22:$G$63) -> 299110168
I5: Repairs (Perbaikan) | K5: =SUMIF($A$22:$A$63,I5,$G$22:$G$63) -> 734192820
A6: Date | B6: Time | C6: Activity | D6: Location | E6: Status | I6: Safety & Deck | K6: =SUMIF($A$22:$A$63,I6,$G$22:$G$63) -> 399868686
A7: 46228 | B7: 0.10833333 | C7: Arrive | D7: Pengerang | E7: Loading | I7: IT & Navigasi | K7: =SUMIF($A$22:$A$63,I7,$G$22:$G$63) -> 191307929
A8: Aug 12 | B8: 0.39583333 | C8: Depart | D8: Pengerang | E8: Loading
A9: Aug 12 | B9: 0.41666667 | C9: Arrive | D9: Tg. Uban | E9: Discharging | I9: Logistik Awal (Initial Supply)
A10: Aug 15 | B10: 0.25 | C10: Depart | D10: Tg. Uban | E10: Discharging | I10: Bunker (BBM) | L10: =SUMIF($A$22:$A$63,I10,$H$22:$H$63) -> 370890
A11: Aug 17 | B11: 0.77916667 | C11: Arrive | D11: Tg. Priok | E11: Discharging | I11: Provision (Makanan) | K11: =SUMIF($A$22:$A$63,I11,$G$22:$G$63) -> 258595682
A12: Aug 20 | B12: 0.79166667 | C12: Depart | D12: Tg. Priok | E12: Discharging
A13: Aug 22 | B13: 0.91666667 | C13: Arrive | D13: Singapore | E13: Bunkering | I13: Operasional Akhir Voyage (Singapore Call & Late Aug)
A14: Aug 26 | B14: 0.083333333 | C14: Depart | D14: Singapore to EOPL | E14: Idle | I14: Navigasi & Service | L14: =SUMIF($A$22:$A$63,I14,$H$22:$H$63) -> 2017
I15: Logistik & Transport | K15: =SUMIF($A$22:$A$63,I15,$G$22:$G$63) -> 104395860
I16: Crew Welfare | K16: =SUMIF($A$22:$A$63,I16,$G$22:$G$63) -> 3336000
A17: OPEX | I17: Komunikasi | K17: =SUMIF($A$22:$A$63,I17,$G$22:$G$63) -> 19000000
A20: Kategori | B20: No. PO | C20: Vendor | D20: Tanggal | E20: Deskripsi Barang/Jasa | F20: Urgensi | G20: Biaya (Grand Total) IDR | H20: Biaya (Grand Total) USD
A21: Pre Voyage & Initial Loading
A22: Legalitas & Survey | B22: 4 | C22: BKI | D22: 46213 | E22: Tank Calibration (Cargo, Slop, FO Tank) | F22: KRITIKAL | G22: 156510000
A23: Legalitas & Survey | B23: 1 | C23: Nereus Subsea | D23: 45883 | E23: Underwater Hull Cleaning & CCTV Survey | F23: TINGGI | H23: 3300
A24: Legalitas & Survey | B24: 28 | C24: Pertamina Marine | D24: 46219 | E24: SIRE 2.0 Inspection Fee | F24: KRITIKAL | G24: 101593087
A25: Legalitas & Survey | C25: EDII (Pelindo) | D25: 46221 | E25: LRIT Conformance Test | F25: WAJIB | G25: 7772365
A26: Legalitas & Survey | B26: 30 | C26: EDII (Pelindo) | D26: 46221 | E26: LRIT Activation (Indonesia NDC) | F26: WAJIB | G26: 13450391
A27: Legalitas & Survey | B27: xxx/SMP/SMUTransliner/VII/2025 | C27: PT Global Lautan Biru | D27: 45827 | E27: Log Books Indonesia. Supply buku jurnal kapal (Deck/Engine/Oil Record) yang sudah disahkan Syahbandar. | F27: Wajib | G27: 19784325
A28: Repairs (Perbaikan) | B28: 6 | C28: Belgi Eng. | D28: 46214 | E28: Repair Anchor Gypsy (Mesin Jangkar) | F28: KRITIKAL | G28: 170000000
A29: Repairs (Perbaikan) | B29: 7 | C29: Belgi Eng. | D29: 46216 | E29: Repair Pipa Kargo & Heating Line | F29: KRITIKAL | G29: 450000000
A30: Repairs (Perbaikan) | B30: 13 | C30: Fazri Multi | D30: 46221 | E30: Repair Lifeboat Crane & Davit | F30: SAFETY | G30: 60775000
A31: Repairs (Perbaikan) | B31: 14 | C31: Belgi Eng. | D31: 46222 | E31: Repair Windlass (STBD) | F31: TINGGI | G31: 9000000
A32: Repairs (Perbaikan) | B32: 15 | C32: Belgi Eng. | D32: 46222 | E32: Supply Material Pipa | F32: TINGGI | G32: 16025000
A33: Repairs (Perbaikan) | B33: 19 | C33: Belgi Eng. | D33: 46225 | E33: Cleaning Engine Room (SIRE Prep) | F33: TINGGI | G33: 17500000
A34: Repairs (Perbaikan) | B34: 16 | C34: SSM | D34: 46224 | E34: Repair N2 Compressor | F34: OPS | G34: 10892820
A35: Safety & Deck | B35: 5 | C35: ITN | D35: 46213 | E35: Vetting Equipment (UTI Tape, Gas Det) | F35: KRITIKAL | G35: 90559350
A36: Safety & Deck | B36: 10 | C36: SSM | D36: 46220 | E36: Second UTI Meter (Cadangan) | F36: KRITIKAL | G36: 89650000
A37: Safety & Deck | B37: 23 | C37: Jaya Samudera | D37: 46228 | E37: Annual Inspection LSA/FFA (Pemadam) | F37: WAJIB | G37: 80000000
A38: Safety & Deck | B38: 12 | C38: Explora | D38: 46221 | E38: Service & Kalibrasi Gas Detector | F38: SAFETY | G38: 23500000
A39: Safety & Deck | B39: 17 | C39: SSM | D39: 46225 | E39: SOPEP Equipment (Oil Spill Kit) | F39: WAJIB | G39: 110558136
... A44: IT & Navigasi | B44: 8 | C44: SSM | D44: 46217 | E44: IT Network (Wifi/Hub/Switch) | F44: SUPPORT | G44: 28675669
A45: IT & Navigasi | B45: xxx/LUL/PO/VIII/2025 | C45: StormGeo Ltd | D45: 13 Aug | E45: S-Planner Subscription. Langganan software navigasi & cuaca tahunan (12 Bulan). | F45: SUPPORT | H45: 494
A46: IT & Navigasi | B46: 18 | C46: SSM | D46: 46225 | E46: Ship Mobile Phone (Samsung) | F46: SUPPORT | G46: 6160000
...

Sheet Voyage 2 Singapore -> Uban -> T
A1: Voyage 2
A3: Route: | B3: Singapore Loading -> Indonesia Discharging -> Singapore Bunkering | I3: Persiapan (Idle di EOPL) | K3: IDR | L3: USD
A4: Duration: | B4: Sep 05 – Sep 30 (25 Days) | I4: Admin & Ops | K4: =SUMIF($A$23:$A$42,I4,$G$23:$G$42) -> 2887650
A5: Note: | B5: Excludes 10 days idle time at EOPL prior to loading | I5: Navigasi | K5: =SUMIF($A$23:$A$42,I5,$G$23:$G$42) -> 3879850
I6: Safety (LSA) | K6: =SUMIF($A$23:$A$42,I6,$G$23:$G$42) -> 30967002
A7: Date | B7: Time | C7: Activity | D7: Location | E7: Status | I7: Komunikasi | K7: =SUMIF($A$23:$A$42,I7,$G$23:$G$42) -> 19000000
A8: 46270 | B8: 0.4375 | C8: Depart | D8: EOPL | E8: Idle | I8: Repair (Deck) | K8: =SUMIF($A$23:$A$42,I8,$G$23:$G$42) -> 26334000
A9: 46270 | B9: 0.70833333 | C9: Arrive | D9: Vopak Singapore | E9: Loading | I9: Deck Store | K9: =SUMIF($A$23:$A$42,I9,$G$23:$G$42) -> 38021940
A10: 46272 | B10: 0.4875 | C10: Depart | D10: Vopak Singapore | E10: Loading | I10: Operasional (Tg. Priok)
A11: 46272 | B11: 0.59583333 | C11: Arrive | D11: Tg. Uban | E11: Discharging | I11: Maintenance | K11: =SUMIF($A$23:$A$42,I11,$G$23:$G$42) -> 23793000
A12: 46278 | B12: 0.47916667 | C12: Depart | D12: Tg. Uban | E12: Discharging | I12: Safety (PPE) | K12: =SUMIF($A$23:$A$42,I12,$G$23:$G$42) -> 33333300
A13: 46281 | B13: 0.14166667 | C13: Arrive | D13: Tg. Priok | E13: Discharging | I13: Admin | K13: =SUMIF($A$23:$A$42,I13,$G$23:$G$42) -> 10441650
A14: 46289 | B14: 0.79583333 | C14: Depart | D14: Tg. Priok | E14: Discharging | I14: Engine Service | K14: =SUMIF($A$23:$A$42,I14,$G$23:$G$42) -> 8325000
A15: 46292 | B15: 0.18333333 | C15: Arrive | D15: Singapore | E15: Bunkering | I15: Logistik | K15: =SUMIF($A$23:$A$42,I15,$G$23:$G$42) -> 2500000
A16: 46295 | B16: 0.0625 | C16: Depart | D16: Singapore | E16: Bunkering | I16: Fresh Water | K16: =SUMIF($A$23:$A$42,I16,$G$23:$G$42) -> 13915000
I17: Engine Spare | K17: Belum ada total
I18: Akhir Voyage (Singapore)
A19: OPEX | I19: Running Store | K19: Belum ada total
I20: Bunker | L20: =SUMIF($A$23:$A$42,I20,$H$23:$H$42) -> 130700
A21: Kategori | B21: No. PO | C21: Vendor | D21: Tanggal | E21: Deskripsi Barang/Jasa | F21: Urgensi | G21: Biaya (Grand Total) IDR | H21: Biaya (Grand Total) USD
A22: Persiapan (Idle di EOPL)
A23: Admin & Ops | B23: 37 | C23: CV Samudera Sumber | D23: 27 Agt | E23: Tinta Printer HP (Refill). Supply tinta Hitam, Kuning, Cyan, Magenta untuk administrasi kapal. | F23: SUPPORT | G23: 2887650
A24: Navigasi | B24: 38 | C24: CV Samudera Sumber | D24: 27 Agt | E24: Wheelhouse Poster. Poster panduan navigasi di anjungan (Appendix 2). | F24: WAJIB | G24: 98325
A25: Safety (LSA) | B25: 39 | C25: PT Samudera Inovasi | D25: 28 Agt | E25: Embarkation Ladder & Rope. Tangga pandu/sekoci 12 Meter + Tali Nilon. | F25: SAFETY | G25: 19450530
A26: Safety (LSA) | B26: 40 | C26: PT Samudera Inovasi | D26: 28 Agt | E26: Pyrotechnics & Signs. Suar tangan (Red Hand Flare) dan stiker simbol keselamatan. | F26: SAFETY | G26: 11516472
A27: Komunikasi | B27: 54 | C27: CV Nusantara Jaya | D27: 31 Agt | E27: Starlink Data Plan. Kuota internet kapal 50GB untuk periode September. | F27: SUPPORT | G27: 19000000
A28: Repair (Deck) | B28: 41 | C28: CV Sumber Laut | D28: 46268 | E28: Copper Tube & Plugs. Material pipa tembaga untuk perbaikan kondensor pendingin (Urgent). | F28: TEKNIS | G28: 26334000
A29: Deck Store | B29: 42 | C29: PT ITN | D29: 46275 | E29: Mooring Rope. 1 Roll Tali Tambat PP Multifilament (Cir 7). | F29: KRITIKAL | G29: 21355290
A30: Operasional (Tg. Priok)
A31: Maintenance | B31: 46 | C31: CV Samudera Sumber | D31: 46280 | E31: Filters (Fleetguard). Filter Oli, BBM, dan Udara untuk maintenance Aux Engine. | F31: RUTIN | G31: 23793000
A32: Safety (PPE) | B32: 43 | C32: PT Sentral Anugrah | D32: 46280 | E32: Wearpack (Coverall). Seragam kerja tahan api (Fire Retardant) untuk kru. | F32: SAFETY | G32: 33333300
A33: Navigasi | B33: 44 | C33: CV Sumber Laut | D33: 46280 | E33: Flags & Shapes. Bendera isyarat dan Bola Hitam (Black Ball). | F33: WAJIB | G33: 3781525
A34: Admin | B34: 45 | C34: CV Sumber Laut | D34: 46280 | E34: Log Books. Buku Jurnal Dek, Mesin, dan Oil Record Book. | F34: WAJIB | G34: 10441650
A35: Engine Service | B35: 47 | C35: PT Altrak 1978 | D35: 46282 | E35: Cummins Engine Inspection. Jasa teknisi inspeksi mesin bantu (KTA 19). | F35: TEKNIS | G35: 8325000
A36: Logistik | B36: 49 | C36: Hapirudin | D36: 46282 | E36: Local Transport. Jasa kirim barang dari pangkalan boat Priok ke Bekasi. | F36: LOGISTIK | G36: 2500000
A37: Fresh Water | B37: 048* | C37: CV Sumber Laut | D37: 46282 | E37: Fresh Water (115 Ton). Pengisian air tawar saat sandar di Jakarta. | F37: WAJIB | G37: 13915000
A38: Deck Store | B38: 50 | C38: PT Samudera Inovasi | D38: 46284 | E38: Pilot Ladder (9 Meter). Tangga pandu operasional. | F38: OPS | G38: 16666650
A39: Engine Spare | B39: CRUZ/E/026/2025 | C39: CV Samudera Sumber | D39: 46288 | E39: Spare Part AE Overhaul. Gasket, Seal, Nozzle untuk overhaul mesin bantu (AE#3). | F39: TEKNIS | G39: Belum ada total
A40: Akhir Voyage (Singapore)
A41: Running Store | B41: 52 | C41: CV Samudera Sumber | D41: 46291 | E41: Engine/Elec Stores. WD-40, Lem, Lampu, Peralatan tangan. | F41: RUTIN | G41: Belum ada total
...

Sheet Voyage 3 Vopak Singapore -> Bau
A1: Voyage 3
A3: Route: | B3: Singapore Loading -> Sulawesi Discharging -> Singapore Bunkering | I3: Operasional (Baubau) | J3: IDR | K3: USD
A4: Duration: | B4: Sep 30 – Oct 30 (30 Days) | I4: Fresh Water | J4: =SUMIF($A$19:$A$23,I4,$G$19:$G$23) -> 21208000
I5: Akhir Voyage (Singapore)
A6: Date | B6: Time | C6: Activity | D6: Location | E6: Status | I6: Bunker (BBM) | K6: =SUMIF($A$19:$A$23,I6,$H$19:$H$23) -> 130700
A7: 46295 | B7: 0.32083333 | C7: Arrive | D7: EOPL | E7: Idle | I7: Maintenance (Deck) | J7: =SUMIF($A$19:$A$23,I7,$G$19:$G$23) -> 23893860
A8: Oct 10 | B8: 0.75833333 | C8: Arrive | D8: Vopak Singapore | E8: Loading
A9: Oct 12 | B9: 0.41666667 | C9: Depart | D9: Vopak Singapore | E9: Loading
A10: Oct 18 | B10: 0.6875 | C10: Arrive | D10: Baubau | E10: Discharging
A11: Oct 22 | B11: 0.89583333 | C11: Depart | D11: Baubau | E11: Discharging
A12: Oct 28 | B12: 0.3125 | C12: Arrive | D12: Singapore | E12: Bunkering
A15: OPEX
A17: Kategori | B17: No. PO | C17: Vendor | D17: Tanggal | E17: Deskripsi Barang/Jasa | F17: Urgensi | G17: Biaya (Grand Total) IDR | H17: Biaya (Grand Total) USD
A18: Operasional (Baubau)
A19: Fresh Water | B19: 58 | C19: CV Sumber Laut Mandiri | D19: 46315 | E19: Fresh Water (via Jetty). Pengisian 80 Ton air tawar saat sandar di pelabuhan Baubau. | F19: WAJIB | G19: 12496000
A20: Fresh Water | B20: 57 | C20: CV Sumber Laut Mandiri | D20: 46315 | E20: Fresh Water (via Transfer Boat). Pengisian tambahan 44 Ton menggunakan kapal transfer (di tengah laut/anchorage). | F20: WAJIB | G20: 8712000
A21: Akhir Voyage (Singapore)
A22: Bunker (BBM) | B22: 55 | C22: KPI OceanConnect | D22: 46322 | E22: Bunker (VLSFO & MGO). Supply BBM di Singapore: 180 MT VLSFO + 50 MT LSMGO. | F22: KRITIKAL | H22: 130700
A23: Maintenance (Deck) | B23: 61 | C23: PT Multipro Paint | D23: 46323 | E23: Cat Kapal (Marine Paint). Supply cat Admicryl & Alkyd Primer untuk perawatan karat di area dek. | F23: MAINTENANCE | G23: 23893860

Sheet Voyage 4 Pengerang -> Baubau ->
A1: Voyage 4
A3: Route: | B3: Malaysia Loading -> Sulawesi & East Java Discharging (Milk Run) | I3: Operasional (Baubau) | K3: IDR
A4: Duration: | B4: Oct 30 – Nov 18 (19 Days) | I4: Fresh Water | K4: =SUMIF($A$20:$A$27,I4,$G$20:$G$27) -> 15620000
I5: Operasional (Surabaya)
A6: Date | B6: Time | C6: Activity | D6: Location | E6: Status | I6: Lube Oil | K6: =SUMIF($A$20:$A$27,I6,$G$20:$G$27) -> 485995518
A7: Oct 30 | B7: 0.75 | C7: Shifting | D7: Pengerang | E7: Loading | I7: Provision (Makanan)
A8: 46328 | B8: 0.38333333 | C8: Depart | D8: Pengerang | E8: Loading | I8: Logistik | K8: =SUMIF($A$20:$A$27,I8,$G$20:$G$27) -> 11385000
A9: 46333 | B9: 0.90833333 | C9: Arrive | D9: Baubau | E9: Discharging
A10: 46335 | B10: 0.41666667 | C10: Depart | D10: Baubau | E10: Discharging
A11: 46338 | B11: 0.041666667 | C11: Arrive | D11: Surabaya | E11: Discharging
A12: 46341 | B12: 0.2 | C12: Depart | D12: Surabaya | E12: Discharging
A13: 46344 | B13: 0.48333333 | C13: Arrive | D13: Pengerang | E13: Idle
A17: OPEX
A19: Kategori | B19: No. PO | C19: Vendor | D19: Tanggal | E19: Deskripsi Barang/Jasa | F19: Urgensi | G19: Biaya (Grand Total) IDR | H19: Biaya (Grand Total) USD
A20: Operasional (Baubau)
A21: Fresh Water | B21: 62 | C21: CV Sumber Laut Mandiri | D21: 46332 | E21: Fresh Water (100 Ton). Pengisian air tawar di Pelabuhan Baubau. | F21: WAJIB | G21: 15620000
A22: Operasional (Surabaya)
A23: Lube Oil | B23: 063* | C23: PT Nusantara Mining Supplies | D23: 46339 | E23: Lube Oil (Oli Mesin). Supply 35 Drum Unimar TBN 40, 15 Drum XD 9000, & 8 Drum Hydraulic Oil. | F23: KRITIKAL | G23: 485995518
A24: Provision (Makanan) | B24: 65 | C24: PT Surya Buana (SBL) | D24: 46334 | E24: Foodstuff Non-Tax. Stok bahan makanan pokok (Sayur, Daging, Beras) periode November. | F24: WAJIB | G24: 71055900
A25: Provision (Makanan) | B25: 64 | C25: PT Surya Buana (SBL) | D25: 46334 | E25: Foodstuff Tax. Makanan kemasan kena pajak (Snack, Bumbu, Susu). | F25: WAJIB | G25: 55806912
A26: Logistik | B26: 66 | C26: PT Surya Buana (SBL) | D26: 46334 | E26: Transport Provision. Biaya pengiriman logistik makanan ke kapal. | F26: SUPPORT | G26: 3885000
A27: Logistik | B27: CRUZ/E/037/2025 | C27: CV Langgeng Jaya Trans | D27: 46336 | E27: Trucking Jakarta - Surabaya. Pengiriman spare part (mungkin oli/cat) via darat untuk naik di Surabaya (ETA 12 Nov). | F27: LOGISTIK | G27: 7500000

Sheet Ringkasan Per Voyage
A1: Voyage 1 | H1: ='Voyage 2 Singapore -> Uban -> T'!A1 -> Voyage 2 | P1: ='Voyage 3 Vopak Singapore -> Bau'!A1 -> Voyage 3 | X1: ='Voyage 4 Pengerang -> Baubau ->'!A1 -> Voyage 4
A3: Route: | C3: Malaysia Loading -> Indonesia Discharging -> Singapore Bunkering | H3: ='Voyage 2 Singapore -> Uban -> T'!A3 -> Route: | J3: ='Voyage 2 Singapore -> Uban -> T'!B3 -> Singapore Loading -> Indonesia Discharging -> Singapore Bunkering | P3: ='Voyage 3 Vopak Singapore -> Bau'!A3 -> Route: | R3: ='Voyage 3 Vopak Singapore -> Bau'!B3 -> Singapore Loading -> Sulawesi Discharging -> Singapore Bunkering | X3: ='Voyage 4 Pengerang -> Baubau ->'!A3 -> Route: | Z3: ='Voyage 4 Pengerang -> Baubau ->'!B3 -> Malaysia Loading -> Sulawesi & East Java Discharging (Milk Run)
A4: Duration: | C4: July 25 – Aug 26 (32 Days) | H4: ='Voyage 2 Singapore -> Uban -> T'!A4 -> Duration: | J4: ='Voyage 2 Singapore -> Uban -> T'!B4 -> Sep 05 – Sep 30 (25 Days) | P4: ='Voyage 3 Vopak Singapore -> Bau'!A4 -> Duration: | R4: ='Voyage 3 Vopak Singapore -> Bau'!B4 -> Sep 30 – Oct 30 (30 Days) | X4: ='Voyage 4 Pengerang -> Baubau ->'!A4 -> Duration: | Z4: ='Voyage 4 Pengerang -> Baubau ->'!B4 -> Oct 30 – Nov 18 (19 Days)
A6: ='Voyage 1 Pengerang -> Uban -> T'!I2 -> Ringkasan Expense OPEX | H6: Ringkasan Expense OPEX | P6: Ringkasan Expense OPEX | X6: Ringkasan Expense OPEX
C7: ='Voyage 1 Pengerang -> Uban -> T'!K2 -> IDR | D7: ='Voyage 1 Pengerang -> Uban -> T'!L2 -> USD | J7: ='Voyage 2 Singapore -> Uban -> T'!K3 -> IDR | K7: ='Voyage 2 Singapore -> Uban -> T'!L3 -> USD | R7: ='Voyage 3 Vopak Singapore -> Bau'!J3 -> IDR | S7: ='Voyage 3 Vopak Singapore -> Bau'!K3 -> USD | Z7: ='Voyage 4 Pengerang -> Baubau ->'!K3 -> IDR
A8: ='Voyage 1 Pengerang -> Uban -> T'!I3 -> Pre Voyage & Initial Loading | H8: ='Voyage 2 Singapore -> Uban -> T'!I3 -> Persiapan (Idle di EOPL) | P8: ='Voyage 3 Vopak Singapore -> Bau'!I3 -> Operasional (Baubau) | X8: ='Voyage 4 Pengerang -> Baubau ->'!I3 -> Operasional (Baubau)
A9: ='Voyage 1 Pengerang -> Uban -> T'!I4 -> Legalitas & Survey | C9: ='Voyage 1 Pengerang -> Uban -> T'!K4 -> 299110168 | H9: ='Voyage 2 Singapore -> Uban -> T'!I4 -> Admin & Ops | J9: ='Voyage 2 Singapore -> Uban -> T'!K4 -> 2887650 | P9: ='Voyage 3 Vopak Singapore -> Bau'!I4 -> Fresh Water | R9: ='Voyage 3 Vopak Singapore -> Bau'!J4 -> 21208000 | X9: ='Voyage 4 Pengerang -> Baubau ->'!I4 -> Fresh Water | Z9: ='Voyage 4 Pengerang -> Baubau ->'!K4 -> 15620000
A10: ='Voyage 1 Pengerang -> Uban -> T'!I5 -> Repairs (Perbaikan) | C10: ='Voyage 1 Pengerang -> Uban -> T'!K5 -> 734192820 | H10: ='Voyage 2 Singapore -> Uban -> T'!I5 -> Navigasi | J10: ='Voyage 2 Singapore -> Uban -> T'!K5 -> 3879850
A11: ='Voyage 1 Pengerang -> Uban -> T'!I6 -> Safety & Deck | C11: ='Voyage 1 Pengerang -> Uban -> T'!K6 -> 399868686 | H11: ='Voyage 2 Singapore -> Uban -> T'!I6 -> Safety (LSA) | J11: ='Voyage 2 Singapore -> Uban -> T'!K6 -> 30967002 | P11: ='Voyage 3 Vopak Singapore -> Bau'!I5 -> Akhir Voyage (Singapore) | X11: ='Voyage 4 Pengerang -> Baubau ->'!I5 -> Operasional (Surabaya) | Z11: ='Voyage 4 Pengerang -> Baubau ->'!K5 -> 0
A12: ='Voyage 1 Pengerang -> Uban -> T'!I7 -> IT & Navigasi | C12: ='Voyage 1 Pengerang -> Uban -> T'!K7 -> 191307929 | H12: ='Voyage 2 Singapore -> Uban -> T'!I7 -> Komunikasi | J12: ='Voyage 2 Singapore -> Uban -> T'!K7 -> 19000000 | P12: ='Voyage 3 Vopak Singapore -> Bau'!I6 -> Bunker (BBM) | S12: ='Voyage 3 Vopak Singapore -> Bau'!K6 -> 130700 | X12: ='Voyage 4 Pengerang -> Baubau ->'!I6 -> Lube Oil | Z12: ='Voyage 4 Pengerang -> Baubau ->'!K6 -> 485995518
H13: ='Voyage 2 Singapore -> Uban -> T'!I8 -> Repair (Deck) | J13: ='Voyage 2 Singapore -> Uban -> T'!K8 -> 26334000 | P13: ='Voyage 3 Vopak Singapore -> Bau'!I7 -> Maintenance (Deck) | R13: ='Voyage 3 Vopak Singapore -> Bau'!J7 -> 23893860
A14: ='Voyage 1 Pengerang -> Uban -> T'!I9 -> Logistik Awal (Initial Supply) | H14: ='Voyage 2 Singapore -> Uban -> T'!I9 -> Deck Store | J14: ='Voyage 2 Singapore -> Uban -> T'!K9 -> 38021940 | X14: ='Voyage 4 Pengerang -> Baubau ->'!I7 -> Provision (Makanan) | Z14: ='Voyage 4 Pengerang -> Baubau ->'!K7 -> 0
A15: ='Voyage 1 Pengerang -> Uban -> T'!I10 -> Bunker (BBM) | D15: ='Voyage 1 Pengerang -> Uban -> T'!L10 -> 370890 | X15: ='Voyage 4 Pengerang -> Baubau ->'!I8 -> Logistik | Z15: ='Voyage 4 Pengerang -> Baubau ->'!K8 -> 11385000
A16: ='Voyage 1 Pengerang -> Uban -> T'!I11 -> Provision (Makanan) | C16: ='Voyage 1 Pengerang -> Uban -> T'!K11 -> 258595682 | H16: ='Voyage 2 Singapore -> Uban -> T'!I10 -> Operasional (Tg. Priok)
H17: ='Voyage 2 Singapore -> Uban -> T'!I11 -> Maintenance | J17: ='Voyage 2 Singapore -> Uban -> T'!K11 -> 23793000
A18: ='Voyage 1 Pengerang -> Uban -> T'!I13 -> Operasional Akhir Voyage (Singapore Call & Late Aug) | H18: ='Voyage 2 Singapore -> Uban -> T'!I12 -> Safety (PPE) | J18: ='Voyage 2 Singapore -> Uban -> T'!K12 -> 33333300
A19: ='Voyage 1 Pengerang -> Uban -> T'!I14 -> Navigasi & Service | D19: ='Voyage 1 Pengerang -> Uban -> T'!L14 -> 2017 | H19: ='Voyage 2 Singapore -> Uban -> T'!I13 -> Admin | J19: ='Voyage 2 Singapore -> Uban -> T'!K13 -> 10441650
A20: ='Voyage 1 Pengerang -> Uban -> T'!I15 -> Logistik & Transport | C20: ='Voyage 1 Pengerang -> Uban -> T'!K15 -> 104395860 | H20: ='Voyage 2 Singapore -> Uban -> T'!I14 -> Engine Service | J20: ='Voyage 2 Singapore -> Uban -> T'!K14 -> 8325000
A21: ='Voyage 1 Pengerang -> Uban -> T'!I16 -> Crew Welfare | C21: ='Voyage 1 Pengerang -> Uban -> T'!K16 -> 3336000 | H21: ='Voyage 2 Singapore -> Uban -> T'!I15 -> Logistik | J21: ='Voyage 2 Singapore -> Uban -> T'!K15 -> 2500000
A22: ='Voyage 1 Pengerang -> Uban -> T'!I17 -> Komunikasi | C22: ='Voyage 1 Pengerang -> Uban -> T'!K17 -> 19000000 | H22: ='Voyage 2 Singapore -> Uban -> T'!I16 -> Fresh Water | J22: ='Voyage 2 Singapore -> Uban -> T'!K16 -> 13915000
H23: ='Voyage 2 Singapore -> Uban -> T'!I17 -> Engine Spare | J23: ='Voyage 2 Singapore -> Uban -> T'!K17 -> Belum ada total
H25: ='Voyage 2 Singapore -> Uban -> T'!I18 -> Akhir Voyage (Singapore)
H26: ='Voyage 2 Singapore -> Uban -> T'!I19 -> Running Store | J26: ='Voyage 2 Singapore -> Uban -> T'!K19 -> Belum ada total
H27: ='Voyage 2 Singapore -> Uban -> T'!I20 -> Bunker | K27: ='Voyage 2 Singapore -> Uban -> T'!L20 -> 130700
A29: Total | C29: =SUM(C9:C22) -> 2009807145 | D29: =SUM(D7:D22) -> 372907 | H29: Total | J29: =SUM(J9:J27) -> 213398392 | K29: =SUM(K8:K27) -> 130700 | P29: Total | R29: =SUM(R8:R27) -> 45101860 | S29: =SUM(S7:S27) -> 130700 | X29: Total | Z29: =SUM(Z8:Z27) -> 513000518

Sheet Voyage 5 Tg. Langsat -> Tg. Pri
A1: Voyage 5
A3: Route: | B3: Malaysia Loading -> West Java Discharging -> Singapore Bunkering | J3: Persiapan Tahun Baru (Navigasi) | L3: IDR | M3: USD | N3: GBP
A4: Duration: | B4: Dec 02 – Dec 15 (13 Days) | J4: Publikasi | L4: =SUMIF($A$18:$A$25,J4,$G$18:$G$25) -> 95095000
A5: Note: | B5: Excludes 14 days idle time at Pengerang prior to shifting | J5: Publikasi (Digital) | N5: =SUMIF($A$18:$A$25,J5,I$18:I$25) -> 906.12
J6: Operasional (Tg. Priok)
A7: Date | B7: Time | C7: Activity | D7: Location | E7: Status | J7: Safety (LSA) | L7: =SUMIF($A$18:$A$25,J7,$G$18:$G$25) -> 9865350
A8: Dec 02 | B8: 0.10833333 | C8: Shifting | D8: Tg. Langsat | E8: Loading | J8: Maintenance (Deck) | L8: =SUMIF($A$18:$A$25,J8,$G$18:$G$25) -> 113276610
A9: Dec 05 | B9: 0.0041666667 | C9: Depart | D9: Tg. Langsat | E9: Loading | J9: Akhir Voyage (Singapore)
A10: Dec 07 | B10: 0.29166667 | C10: Arrive | D10: Tg. Priok | E10: Discharging | J10: Bunker (BBM) | L10: =SUMIF($A$18:$A$25,J10,G$18:G$25) -> 0 | M10: =SUMIF($A$18:$A$25,J10,H$18:H$25) -> 37250 | N10: =SUMIF($A$18:$A$25,J10,I$18:I$25) -> 0
A11: Dec 11 | B11: 0.50833333 | C11: Depart | D11: Tg. Priok | E11: Discharging
A12: Dec 14 | B12: 0.29166667 | C12: Arrive | D12: Singapore | E12: Bunkering
A13: Dec 15 | B13: 0.725 | C13: Shifting | D13: Singapore (Berth) | E13: Loading
A15: OPEX
A17: Kategori | B17: No. PO | C17: Vendor | D17: Tanggal | E17: Deskripsi Barang/Jasa | F17: Urgensi | G17: Biaya (Grand Total) IDR | H17: Biaya (Grand Total) USD | I17: Biaya (Grand Total) GBP
A18: Persiapan Tahun Baru (Navigasi)
A19: Publikasi | B19: 68 | C19: CV Sumber Laut Mandiri | D19: 46360 | E19: Peta & Buku Navigasi (Fisik). Supply Peta BA Chart (Singapore/Malacca Strait), STS Guide, ISGOTT edisi terbaru 2025/2026. | F19: WAJIB REGULASI | G19: 95095000
A20: Publikasi (Digital) | B20: 69 | C20: StormGeo | D20: 46360 | E20: E-Books & Software. Langganan digital List of Radio Signals, IMO Books, & Cyber Security Workbook. | F20: WAJIB REGULASI | I20: 906.12
A21: Operasional (Tg. Priok)
A22: Safety (LSA) | B22: 070 R1 | C22: CV Sumber Laut Mandiri | D22: 46365 | E22: Safety Equipment. Suar tangan (Red Hand Flare), Smoke Signal, dan Sabuk Pengaman Sekoci (Seat Belt 4 Point). | F22: SAFETY | G22: 9865350
A23: Maintenance (Deck) | B23: 061 R1 | C23: PT Jotun Indonesia | D23: 46367 | E23: Cat Kapal (Marine Paint). Supply besar cat Hardtop XP, Pioner TC, Jotamastic, Alkydprimer untuk perawatan bodi kapal. | F23: MAINTENANCE | G23: 113276610
A24: Akhir Voyage (Singapore)
A25: Bunker (BBM) | B25: 71 | C25: Suvarna Energia | D25: 46370 | E25: Bunker (LSMGO 50 MT). Pengisian Solar (MGO) di Singapura. | F25: KRITIKAL | H25: 37250

Sheet Voyage 6 Singapore -> Kotabaru
A1: Voyage 6
A3: Route: | B3: Singapore Loading -> Kalimantan Discharging -> Singapore Return
A4: Duration: | B4: Dec 15 – Jan 04 (20 Days)
A6: Date | B6: Time | C6: Activity | D6: Location | E6: Status
A7: Dec 15 | B7: 0.725 | C7: Shifting | D7: Singapore (Berth) | E7: Loading
A8: Dec 18 | B8: 0.30416667 | C8: Depart | D8: Singapore | E8: Loading
A9: Dec 22 | B9: 0.29166667 | C9: Arrive | D9: Kotabaru | E9: Discharging
A10: Dec 27 | B10: 0.375 | C10: Depart | D10: Kotabaru | E10: Discharging
A11: Dec 31 | B11: 0.97916667 | C11: Arrive | D11: Singapore | E11: Bunkering
A12: 46026 | B12: 0.2 | C12: Shifting | D12: Singapore (Berth) | E12: Loading
A14: OPEX
A16: Kategori | B16: No. PO | C16: Vendor | D16: Tanggal | E16: Deskripsi Barang/Jasa | F16: Urgensi | G16: Biaya (Grand Total) | H16: Term of Payment (TOP)
A17: Persiapan (Singapore)
A18: Bunker (BBM) | B18: 071* | C18: Suvarna Energia | D18: 46370 | E18: Bunker (LSMGO 50 MT). Pengisian Solar (MGO) di Singapore sehari sebelum shifting ke dermaga muat. Stok ini digunakan untuk operasional mesin selama perjalanan ke Kotabaru. | F18: KRITIKAL | G18: 37250 | H18: 30 Days after delivery

Sheet Sheet1 (1)
B2: Date | C2: Time | D2: Remark | E2: Status
B3: 45863 | C3: 0.10833333 | D3: Arrive Pengerang | E3: Loading
B4: 45881 | C4: 0.39583333 | D4: Dept. Pengerang | E4: Loading
B5: 45881 | C5: 0.41666667 | D5: Arrive Tg. Uban | E5: Discharging
B6: 45884 | C6: 0.25 | D6: Dept. Tg. Uban | E6: Discharging
B7: 45886 | C7: 0.77916667 | D7: Arrive Tg. Priok | E7: Discharging
B8: 45889 | C8: 0.79166667 | D8: Dept. Tg. Priok | E8: Discharging
B9: 45891 | C9: 0.91666667 | D9: Arrive Singapore | E9: Bunkering
B10: 45895 | C10: 0.083333333 | D10: Dept. Singapore to EOPL | E10: Idle
B11: 45905 | C11: 0.4375 | D11: Dept. EOPL | E11: Idle
B12: 45905 | C12: 0.70833333 | D12: Arrive Vopax Singapore | E12: Loading
B13: 45907 | C13: 0.4875 | D13: Dept. Vopax Singapore | E13: Loading
B14: 45907 | C14: 0.59583333 | D14: Arrive Tg. Uban | E14: Discharging
... B43: 46026 | C43: 0.2 | D43: Shifting for berthing at Singapore | E43: Loading
